2020-04-22 10:25:12,538 ERROR: Exception on /search [GET] [in /home/julian/tawachai/venv/lib/python3.8/site-packages/flask/app.py:1891]
Traceback (most recent call last):
  File "/home/julian/tawachai/venv/lib/python3.8/site-packages/flask/app.py", line 2447, in wsgi_app
    response = self.full_dispatch_request()
  File "/home/julian/tawachai/venv/lib/python3.8/site-packages/flask/app.py", line 1952, in full_dispatch_request
    rv = self.handle_user_exception(e)
  File "/home/julian/tawachai/venv/lib/python3.8/site-packages/flask/app.py", line 1821, in handle_user_exception
    reraise(exc_type, exc_value, tb)
  File "/home/julian/tawachai/venv/lib/python3.8/site-packages/flask/_compat.py", line 39, in reraise
    raise value
  File "/home/julian/tawachai/venv/lib/python3.8/site-packages/flask/app.py", line 1950, in full_dispatch_request
    rv = self.dispatch_request()
  File "/home/julian/tawachai/venv/lib/python3.8/site-packages/flask/app.py", line 1936, in dispatch_request
    return self.view_functions[rule.endpoint](**req.view_args)
  File "/home/julian/tawachai/venv/lib/python3.8/site-packages/flask_login/utils.py", line 272, in decorated_view
    return func(*args, **kwargs)
  File "/home/julian/tawachai/app/main/routes.py", line 89, in search
    current_app.config['POSTS_PER_PAGE'])
KeyError: 'POSTS_PER_PAGE'
2020-04-22 10:27:18,514 INFO: tawachai startup [in /home/julian/tawachai/app/__init__.py:70]
2020-04-22 10:28:10,345 INFO: tawachai startup [in /home/julian/tawachai/app/__init__.py:70]
2020-04-22 10:29:49,540 INFO: tawachai startup [in /home/julian/tawachai/app/__init__.py:70]
2020-04-22 11:01:09,556 INFO: tawachai startup [in /home/julian/tawachai/app/__init__.py:75]
2020-04-22 11:01:20,600 INFO: tawachai startup [in /home/julian/tawachai/app/__init__.py:75]
2020-04-22 11:01:28,484 INFO: tawachai startup [in /home/julian/tawachai/app/__init__.py:75]
2020-04-22 11:08:42,135 INFO: tawachai startup [in /home/julian/tawachai/app/__init__.py:75]
2020-04-22 16:02:13,025 INFO: tawachai startup [in /home/julian/tawachai/app/__init__.py:75]
2020-04-22 16:02:16,822 ERROR: Exception on / [GET] [in /home/julian/tawachai/venv/lib/python3.8/site-packages/flask/app.py:1891]
Traceback (most recent call last):
  File "/home/julian/tawachai/venv/lib/python3.8/site-packages/flask/app.py", line 2447, in wsgi_app
    response = self.full_dispatch_request()
  File "/home/julian/tawachai/venv/lib/python3.8/site-packages/flask/app.py", line 1952, in full_dispatch_request
    rv = self.handle_user_exception(e)
  File "/home/julian/tawachai/venv/lib/python3.8/site-packages/flask/app.py", line 1821, in handle_user_exception
    reraise(exc_type, exc_value, tb)
  File "/home/julian/tawachai/venv/lib/python3.8/site-packages/flask/_compat.py", line 39, in reraise
    raise value
  File "/home/julian/tawachai/venv/lib/python3.8/site-packages/flask/app.py", line 1950, in full_dispatch_request
    rv = self.dispatch_request()
  File "/home/julian/tawachai/venv/lib/python3.8/site-packages/flask/app.py", line 1936, in dispatch_request
    return self.view_functions[rule.endpoint](**req.view_args)
  File "/home/julian/tawachai/venv/lib/python3.8/site-packages/flask_login/utils.py", line 272, in decorated_view
    return func(*args, **kwargs)
  File "/home/julian/tawachai/app/main/routes.py", line 34, in index
    page, current_app.config['PROJECTS_PER_PAGE'], False)
KeyError: 'PROJECTS_PER_PAGE'
2020-04-22 16:02:49,442 INFO: tawachai startup [in /home/julian/tawachai/app/__init__.py:75]
2020-04-22 16:40:46,555 INFO: tawachai startup [in /home/julian/tawachai/app/__init__.py:75]
2020-04-22 16:41:06,695 INFO: tawachai startup [in /home/julian/tawachai/app/__init__.py:75]
2020-04-22 16:41:17,587 INFO: tawachai startup [in /home/julian/tawachai/app/__init__.py:75]
2020-04-22 16:51:41,366 INFO: tawachai startup [in /home/julian/tawachai/app/__init__.py:75]
2020-04-22 16:52:32,190 ERROR: Exception on /favicon.ico [GET] [in /home/julian/tawachai/venv/lib/python3.8/site-packages/flask/app.py:1891]
Traceback (most recent call last):
  File "/home/julian/tawachai/venv/lib/python3.8/site-packages/flask/app.py", line 1950, in full_dispatch_request
    rv = self.dispatch_request()
  File "/home/julian/tawachai/venv/lib/python3.8/site-packages/flask/app.py", line 1926, in dispatch_request
    self.raise_routing_exception(req)
  File "/home/julian/tawachai/venv/lib/python3.8/site-packages/flask/app.py", line 1908, in raise_routing_exception
    raise request.routing_exception
  File "/home/julian/tawachai/venv/lib/python3.8/site-packages/flask/ctx.py", line 350, in match_request
    result = self.url_adapter.match(return_rule=True)
  File "/home/julian/tawachai/venv/lib/python3.8/site-packages/werkzeug/routing.py", line 1945, in match
    raise NotFound()
werkzeug.exceptions.NotFound: 404 Not Found: The requested URL was not found on the server. If you entered the URL manually please check your spelling and try again.

During handling of the above exception, another exception occurred:

Traceback (most recent call last):
  File "/home/julian/tawachai/venv/lib/python3.8/site-packages/flask/app.py", line 2447, in wsgi_app
    response = self.full_dispatch_request()
  File "/home/julian/tawachai/venv/lib/python3.8/site-packages/flask/app.py", line 1952, in full_dispatch_request
    rv = self.handle_user_exception(e)
  File "/home/julian/tawachai/venv/lib/python3.8/site-packages/flask/app.py", line 1816, in handle_user_exception
    return self.handle_http_exception(e)
  File "/home/julian/tawachai/venv/lib/python3.8/site-packages/flask/app.py", line 1744, in handle_http_exception
    return handler(e)
  File "/home/julian/tawachai/app/errors/handlers.py", line 7, in not_found_error
    return render_template('errors/404.html'), 404
  File "/home/julian/tawachai/venv/lib/python3.8/site-packages/flask/templating.py", line 138, in render_template
    ctx.app.jinja_env.get_or_select_template(template_name_or_list),
  File "/home/julian/tawachai/venv/lib/python3.8/site-packages/jinja2/environment.py", line 930, in get_or_select_template
    return self.get_template(template_name_or_list, parent, globals)
  File "/home/julian/tawachai/venv/lib/python3.8/site-packages/jinja2/environment.py", line 883, in get_template
    return self._load_template(name, self.make_globals(globals))
  File "/home/julian/tawachai/venv/lib/python3.8/site-packages/jinja2/environment.py", line 857, in _load_template
    template = self.loader.load(self, name, globals)
  File "/home/julian/tawachai/venv/lib/python3.8/site-packages/jinja2/loaders.py", line 127, in load
    code = environment.compile(source, name, filename)
  File "/home/julian/tawachai/venv/lib/python3.8/site-packages/jinja2/environment.py", line 638, in compile
    self.handle_exception(source=source_hint)
  File "/home/julian/tawachai/venv/lib/python3.8/site-packages/jinja2/environment.py", line 832, in handle_exception
    reraise(*rewrite_traceback_stack(source=source))
  File "/home/julian/tawachai/venv/lib/python3.8/site-packages/jinja2/_compat.py", line 28, in reraise
    raise value.with_traceback(tb)
  File "/home/julian/tawachai/app/templates/errors/404.html", line 8, in template
    {% endblock %}
jinja2.exceptions.TemplateSyntaxError: Unexpected end of template. Jinja was looking for the following tags: 'endblock'. The innermost block that needs to be closed is 'block'.
2020-04-22 16:54:04,225 INFO: tawachai startup [in /home/julian/tawachai/app/__init__.py:75]
